2023-08-03 16:09:22,862 : ERROR : BINANCE_DELIVERY: Failed to parse symbol information: 451 Client Error:  for url: https://dapi.binance.com/dapi/v1/exchangeInfo
Traceback (most recent call last):
  File "/Library/Frameworks/Python.framework/Versions/3.10/lib/python3.10/site-packages/cryptofeed/exchange.py", line 103, in symbol_mapping
    data.append(cls.http_sync.read(addr, json=True, uuid=cls.id))
  File "/Library/Frameworks/Python.framework/Versions/3.10/lib/python3.10/site-packages/cryptofeed/connection.py", line 55, in read
    return self.process_response(r, address, json=json, text=text, uuid=uuid)
  File "/Library/Frameworks/Python.framework/Versions/3.10/lib/python3.10/site-packages/cryptofeed/connection.py", line 45, in process_response
    r.raise_for_status()
  File "/Library/Frameworks/Python.framework/Versions/3.10/lib/python3.10/site-packages/requests/models.py", line 1021, in raise_for_status
    raise HTTPError(http_error_msg, response=self)
requests.exceptions.HTTPError: 451 Client Error:  for url: https://dapi.binance.com/dapi/v1/exchangeInfo
2023-08-03 16:10:11,696 : ERROR : BINANCE_DELIVERY: Failed to parse symbol information: 451 Client Error:  for url: https://dapi.binance.com/dapi/v1/exchangeInfo
Traceback (most recent call last):
  File "/Library/Frameworks/Python.framework/Versions/3.10/lib/python3.10/site-packages/cryptofeed/exchange.py", line 103, in symbol_mapping
    data.append(cls.http_sync.read(addr, json=True, uuid=cls.id))
  File "/Library/Frameworks/Python.framework/Versions/3.10/lib/python3.10/site-packages/cryptofeed/connection.py", line 55, in read
    return self.process_response(r, address, json=json, text=text, uuid=uuid)
  File "/Library/Frameworks/Python.framework/Versions/3.10/lib/python3.10/site-packages/cryptofeed/connection.py", line 45, in process_response
    r.raise_for_status()
  File "/Library/Frameworks/Python.framework/Versions/3.10/lib/python3.10/site-packages/requests/models.py", line 1021, in raise_for_status
    raise HTTPError(http_error_msg, response=self)
requests.exceptions.HTTPError: 451 Client Error:  for url: https://dapi.binance.com/dapi/v1/exchangeInfo
2023-08-03 16:10:12,368 : ERROR : BINANCE_FUTURES: Failed to parse symbol information: 451 Client Error:  for url: https://fapi.binance.com/fapi/v1/exchangeInfo
Traceback (most recent call last):
  File "/Library/Frameworks/Python.framework/Versions/3.10/lib/python3.10/site-packages/cryptofeed/exchange.py", line 103, in symbol_mapping
    data.append(cls.http_sync.read(addr, json=True, uuid=cls.id))
  File "/Library/Frameworks/Python.framework/Versions/3.10/lib/python3.10/site-packages/cryptofeed/connection.py", line 55, in read
    return self.process_response(r, address, json=json, text=text, uuid=uuid)
  File "/Library/Frameworks/Python.framework/Versions/3.10/lib/python3.10/site-packages/cryptofeed/connection.py", line 45, in process_response
    r.raise_for_status()
  File "/Library/Frameworks/Python.framework/Versions/3.10/lib/python3.10/site-packages/requests/models.py", line 1021, in raise_for_status
    raise HTTPError(http_error_msg, response=self)
requests.exceptions.HTTPError: 451 Client Error:  for url: https://fapi.binance.com/fapi/v1/exchangeInfo
2023-08-03 16:10:13,013 : ERROR : BINANCE_TR: Failed to parse symbol information: 451 Client Error:  for url: https://api.binance.me/api/v3/exchangeInfo
Traceback (most recent call last):
  File "/Library/Frameworks/Python.framework/Versions/3.10/lib/python3.10/site-packages/cryptofeed/exchange.py", line 103, in symbol_mapping
    data.append(cls.http_sync.read(addr, json=True, uuid=cls.id))
  File "/Library/Frameworks/Python.framework/Versions/3.10/lib/python3.10/site-packages/cryptofeed/connection.py", line 55, in read
    return self.process_response(r, address, json=json, text=text, uuid=uuid)
  File "/Library/Frameworks/Python.framework/Versions/3.10/lib/python3.10/site-packages/cryptofeed/connection.py", line 45, in process_response
    r.raise_for_status()
  File "/Library/Frameworks/Python.framework/Versions/3.10/lib/python3.10/site-packages/requests/models.py", line 1021, in raise_for_status
    raise HTTPError(http_error_msg, response=self)
requests.exceptions.HTTPError: 451 Client Error:  for url: https://api.binance.me/api/v3/exchangeInfo
2023-08-03 16:10:13,164 : ERROR : BINANCE: Failed to parse symbol information: 451 Client Error:  for url: https://api.binance.com/api/v3/exchangeInfo
Traceback (most recent call last):
  File "/Library/Frameworks/Python.framework/Versions/3.10/lib/python3.10/site-packages/cryptofeed/exchange.py", line 103, in symbol_mapping
    data.append(cls.http_sync.read(addr, json=True, uuid=cls.id))
  File "/Library/Frameworks/Python.framework/Versions/3.10/lib/python3.10/site-packages/cryptofeed/connection.py", line 55, in read
    return self.process_response(r, address, json=json, text=text, uuid=uuid)
  File "/Library/Frameworks/Python.framework/Versions/3.10/lib/python3.10/site-packages/cryptofeed/connection.py", line 45, in process_response
    r.raise_for_status()
  File "/Library/Frameworks/Python.framework/Versions/3.10/lib/python3.10/site-packages/requests/models.py", line 1021, in raise_for_status
    raise HTTPError(http_error_msg, response=self)
requests.exceptions.HTTPError: 451 Client Error:  for url: https://api.binance.com/api/v3/exchangeInfo
2023-08-03 16:10:24,557 : ERROR : BYBIT: Failed to parse symbol information: 403 Client Error: Forbidden for url: https://api.bybit.com/v2/public/symbols
Traceback (most recent call last):
  File "/Library/Frameworks/Python.framework/Versions/3.10/lib/python3.10/site-packages/cryptofeed/exchange.py", line 103, in symbol_mapping
    data.append(cls.http_sync.read(addr, json=True, uuid=cls.id))
  File "/Library/Frameworks/Python.framework/Versions/3.10/lib/python3.10/site-packages/cryptofeed/connection.py", line 55, in read
    return self.process_response(r, address, json=json, text=text, uuid=uuid)
  File "/Library/Frameworks/Python.framework/Versions/3.10/lib/python3.10/site-packages/cryptofeed/connection.py", line 45, in process_response
    r.raise_for_status()
  File "/Library/Frameworks/Python.framework/Versions/3.10/lib/python3.10/site-packages/requests/models.py", line 1021, in raise_for_status
    raise HTTPError(http_error_msg, response=self)
requests.exceptions.HTTPError: 403 Client Error: Forbidden for url: https://api.bybit.com/v2/public/symbols
2023-08-03 16:10:27,534 : ERROR : DERIBIT: Failed to parse symbol information: 'settlement_period'
Traceback (most recent call last):
  File "/Library/Frameworks/Python.framework/Versions/3.10/lib/python3.10/site-packages/cryptofeed/exchange.py", line 105, in symbol_mapping
    syms, info = cls._parse_symbol_data(data if len(data) > 1 else data[0])
  File "/Library/Frameworks/Python.framework/Versions/3.10/lib/python3.10/site-packages/cryptofeed/exchanges/deribit.py", line 62, in _parse_symbol_data
    stype = e['kind'] if e['settlement_period'] != 'perpetual' else PERPETUAL
KeyError: 'settlement_period'
2023-08-03 16:10:28,716 : ERROR : DELTA: Failed to parse symbol information: options_combos
Traceback (most recent call last):
  File "/Library/Frameworks/Python.framework/Versions/3.10/lib/python3.10/site-packages/cryptofeed/exchange.py", line 105, in symbol_mapping
    syms, info = cls._parse_symbol_data(data if len(data) > 1 else data[0])
  File "/Library/Frameworks/Python.framework/Versions/3.10/lib/python3.10/site-packages/cryptofeed/exchanges/delta.py", line 62, in _parse_symbol_data
    raise ValueError(entry['contract_type'])
ValueError: options_combos
2023-08-03 16:10:29,548 : ERROR : EXX: Failed to parse symbol information: HTTPSConnectionPool(host='api.exx.com', port=443): Max retries exceeded with url: /data/v1/tickers (Caused by NewConnectionError('<urllib3.connection.HTTPSConnection object at 0x1065b3880>: Failed to establish a new connection: [Errno 8] nodename nor servname provided, or not known'))
Traceback (most recent call last):
  File "/Library/Frameworks/Python.framework/Versions/3.10/lib/python3.10/site-packages/urllib3/connection.py", line 174, in _new_conn
    conn = connection.create_connection(
  File "/Library/Frameworks/Python.framework/Versions/3.10/lib/python3.10/site-packages/urllib3/util/connection.py", line 72, in create_connection
    for res in socket.getaddrinfo(host, port, family, socket.SOCK_STREAM):
  File "/Library/Frameworks/Python.framework/Versions/3.10/lib/python3.10/socket.py", line 955, in getaddrinfo
    for res in _socket.getaddrinfo(host, port, family, type, proto, flags):
socket.gaierror: [Errno 8] nodename nor servname provided, or not known

During handling of the above exception, another exception occurred:

Traceback (most recent call last):
  File "/Library/Frameworks/Python.framework/Versions/3.10/lib/python3.10/site-packages/urllib3/connectionpool.py", line 703, in urlopen
    httplib_response = self._make_request(
  File "/Library/Frameworks/Python.framework/Versions/3.10/lib/python3.10/site-packages/urllib3/connectionpool.py", line 386, in _make_request
    self._validate_conn(conn)
  File "/Library/Frameworks/Python.framework/Versions/3.10/lib/python3.10/site-packages/urllib3/connectionpool.py", line 1042, in _validate_conn
    conn.connect()
  File "/Library/Frameworks/Python.framework/Versions/3.10/lib/python3.10/site-packages/urllib3/connection.py", line 358, in connect
    self.sock = conn = self._new_conn()
  File "/Library/Frameworks/Python.framework/Versions/3.10/lib/python3.10/site-packages/urllib3/connection.py", line 186, in _new_conn
    raise NewConnectionError(
urllib3.exceptions.NewConnectionError: <urllib3.connection.HTTPSConnection object at 0x1065b3880>: Failed to establish a new connection: [Errno 8] nodename nor servname provided, or not known

During handling of the above exception, another exception occurred:

Traceback (most recent call last):
  File "/Library/Frameworks/Python.framework/Versions/3.10/lib/python3.10/site-packages/requests/adapters.py", line 489, in send
    resp = conn.urlopen(
  File "/Library/Frameworks/Python.framework/Versions/3.10/lib/python3.10/site-packages/urllib3/connectionpool.py", line 787, in urlopen
    retries = retries.increment(
  File "/Library/Frameworks/Python.framework/Versions/3.10/lib/python3.10/site-packages/urllib3/util/retry.py", line 592, in increment
    raise MaxRetryError(_pool, url, error or ResponseError(cause))
urllib3.exceptions.MaxRetryError: HTTPSConnectionPool(host='api.exx.com', port=443): Max retries exceeded with url: /data/v1/tickers (Caused by NewConnectionError('<urllib3.connection.HTTPSConnection object at 0x1065b3880>: Failed to establish a new connection: [Errno 8] nodename nor servname provided, or not known'))

During handling of the above exception, another exception occurred:

Traceback (most recent call last):
  File "/Library/Frameworks/Python.framework/Versions/3.10/lib/python3.10/site-packages/cryptofeed/exchange.py", line 103, in symbol_mapping
    data.append(cls.http_sync.read(addr, json=True, uuid=cls.id))
  File "/Library/Frameworks/Python.framework/Versions/3.10/lib/python3.10/site-packages/cryptofeed/connection.py", line 54, in read
    r = requests.get(address, headers=headers, params=params)
  File "/Library/Frameworks/Python.framework/Versions/3.10/lib/python3.10/site-packages/requests/api.py", line 73, in get
    return request("get", url, params=params, **kwargs)
  File "/Library/Frameworks/Python.framework/Versions/3.10/lib/python3.10/site-packages/requests/api.py", line 59, in request
    return session.request(method=method, url=url, **kwargs)
  File "/Library/Frameworks/Python.framework/Versions/3.10/lib/python3.10/site-packages/requests/sessions.py", line 587, in request
    resp = self.send(prep, **send_kwargs)
  File "/Library/Frameworks/Python.framework/Versions/3.10/lib/python3.10/site-packages/requests/sessions.py", line 701, in send
    r = adapter.send(request, **kwargs)
  File "/Library/Frameworks/Python.framework/Versions/3.10/lib/python3.10/site-packages/requests/adapters.py", line 565, in send
    raise ConnectionError(e, request=request)
requests.exceptions.ConnectionError: HTTPSConnectionPool(host='api.exx.com', port=443): Max retries exceeded with url: /data/v1/tickers (Caused by NewConnectionError('<urllib3.connection.HTTPSConnection object at 0x1065b3880>: Failed to establish a new connection: [Errno 8] nodename nor servname provided, or not known'))
2023-08-03 16:11:24,814 : ERROR : KRAKEN_FUTURES: Failed to parse symbol information: 'FF'
Traceback (most recent call last):
  File "/Library/Frameworks/Python.framework/Versions/3.10/lib/python3.10/site-packages/cryptofeed/exchange.py", line 105, in symbol_mapping
    syms, info = cls._parse_symbol_data(data if len(data) > 1 else data[0])
  File "/Library/Frameworks/Python.framework/Versions/3.10/lib/python3.10/site-packages/cryptofeed/exchanges/kraken_futures.py", line 73, in _parse_symbol_data
    info['product_type'][s.normalized] = _kraken_futures_product_type[ftype]
KeyError: 'FF'
2023-08-03 16:11:25,671 : ERROR : OKCOIN: Failed to parse symbol information: 502 Server Error: Bad Gateway for url: https://www.okcoin.com/api/spot/v3/instruments
Traceback (most recent call last):
  File "/Library/Frameworks/Python.framework/Versions/3.10/lib/python3.10/site-packages/cryptofeed/exchange.py", line 103, in symbol_mapping
    data.append(cls.http_sync.read(addr, json=True, uuid=cls.id))
  File "/Library/Frameworks/Python.framework/Versions/3.10/lib/python3.10/site-packages/cryptofeed/connection.py", line 55, in read
    return self.process_response(r, address, json=json, text=text, uuid=uuid)
  File "/Library/Frameworks/Python.framework/Versions/3.10/lib/python3.10/site-packages/cryptofeed/connection.py", line 45, in process_response
    r.raise_for_status()
  File "/Library/Frameworks/Python.framework/Versions/3.10/lib/python3.10/site-packages/requests/models.py", line 1021, in raise_for_status
    raise HTTPError(http_error_msg, response=self)
requests.exceptions.HTTPError: 502 Server Error: Bad Gateway for url: https://www.okcoin.com/api/spot/v3/instruments
2023-08-03 16:14:00,682 : WARNING : BITMEX.ws.2: received no messages within timeout, restarting connection
2023-08-03 16:18:34,680 : ERROR : BINANCE: Failed to parse symbol information: 451 Client Error:  for url: https://api.binance.com/api/v3/exchangeInfo
Traceback (most recent call last):
  File "/Library/Frameworks/Python.framework/Versions/3.10/lib/python3.10/site-packages/cryptofeed/exchange.py", line 103, in symbol_mapping
    data.append(cls.http_sync.read(addr, json=True, uuid=cls.id))
  File "/Library/Frameworks/Python.framework/Versions/3.10/lib/python3.10/site-packages/cryptofeed/connection.py", line 55, in read
    return self.process_response(r, address, json=json, text=text, uuid=uuid)
  File "/Library/Frameworks/Python.framework/Versions/3.10/lib/python3.10/site-packages/cryptofeed/connection.py", line 45, in process_response
    r.raise_for_status()
  File "/Library/Frameworks/Python.framework/Versions/3.10/lib/python3.10/site-packages/requests/models.py", line 1021, in raise_for_status
    raise HTTPError(http_error_msg, response=self)
requests.exceptions.HTTPError: 451 Client Error:  for url: https://api.binance.com/api/v3/exchangeInfo
2023-08-03 16:19:31,603 : ERROR : BINANCE: Failed to parse symbol information: 451 Client Error:  for url: https://api.binance.com/api/v3/exchangeInfo
Traceback (most recent call last):
  File "/Library/Frameworks/Python.framework/Versions/3.10/lib/python3.10/site-packages/cryptofeed/exchange.py", line 103, in symbol_mapping
    data.append(cls.http_sync.read(addr, json=True, uuid=cls.id))
  File "/Library/Frameworks/Python.framework/Versions/3.10/lib/python3.10/site-packages/cryptofeed/connection.py", line 55, in read
    return self.process_response(r, address, json=json, text=text, uuid=uuid)
  File "/Library/Frameworks/Python.framework/Versions/3.10/lib/python3.10/site-packages/cryptofeed/connection.py", line 45, in process_response
    r.raise_for_status()
  File "/Library/Frameworks/Python.framework/Versions/3.10/lib/python3.10/site-packages/requests/models.py", line 1021, in raise_for_status
    raise HTTPError(http_error_msg, response=self)
requests.exceptions.HTTPError: 451 Client Error:  for url: https://api.binance.com/api/v3/exchangeInfo
2023-08-07 16:27:29,869 : ERROR : BINANCE: Failed to parse symbol information: 451 Client Error:  for url: https://api.binance.com/api/v3/exchangeInfo
Traceback (most recent call last):
  File "/Library/Frameworks/Python.framework/Versions/3.10/lib/python3.10/site-packages/cryptofeed/exchange.py", line 103, in symbol_mapping
    data.append(cls.http_sync.read(addr, json=True, uuid=cls.id))
  File "/Library/Frameworks/Python.framework/Versions/3.10/lib/python3.10/site-packages/cryptofeed/connection.py", line 55, in read
    return self.process_response(r, address, json=json, text=text, uuid=uuid)
  File "/Library/Frameworks/Python.framework/Versions/3.10/lib/python3.10/site-packages/cryptofeed/connection.py", line 45, in process_response
    r.raise_for_status()
  File "/Library/Frameworks/Python.framework/Versions/3.10/lib/python3.10/site-packages/requests/models.py", line 1021, in raise_for_status
    raise HTTPError(http_error_msg, response=self)
requests.exceptions.HTTPError: 451 Client Error:  for url: https://api.binance.com/api/v3/exchangeInfo
2023-08-07 16:28:40,563 : ERROR : BINANCE: Failed to parse symbol information: 451 Client Error:  for url: https://api.binance.com/api/v3/exchangeInfo
Traceback (most recent call last):
  File "/Library/Frameworks/Python.framework/Versions/3.10/lib/python3.10/site-packages/cryptofeed/exchange.py", line 103, in symbol_mapping
    data.append(cls.http_sync.read(addr, json=True, uuid=cls.id))
  File "/Library/Frameworks/Python.framework/Versions/3.10/lib/python3.10/site-packages/cryptofeed/connection.py", line 55, in read
    return self.process_response(r, address, json=json, text=text, uuid=uuid)
  File "/Library/Frameworks/Python.framework/Versions/3.10/lib/python3.10/site-packages/cryptofeed/connection.py", line 45, in process_response
    r.raise_for_status()
  File "/Library/Frameworks/Python.framework/Versions/3.10/lib/python3.10/site-packages/requests/models.py", line 1021, in raise_for_status
    raise HTTPError(http_error_msg, response=self)
requests.exceptions.HTTPError: 451 Client Error:  for url: https://api.binance.com/api/v3/exchangeInfo
2023-08-07 16:30:03,356 : ERROR : BINANCE_FUTURES: Failed to parse symbol information: 451 Client Error:  for url: https://fapi.binance.com/fapi/v1/exchangeInfo
Traceback (most recent call last):
  File "/Library/Frameworks/Python.framework/Versions/3.10/lib/python3.10/site-packages/cryptofeed/exchange.py", line 103, in symbol_mapping
    data.append(cls.http_sync.read(addr, json=True, uuid=cls.id))
  File "/Library/Frameworks/Python.framework/Versions/3.10/lib/python3.10/site-packages/cryptofeed/connection.py", line 55, in read
    return self.process_response(r, address, json=json, text=text, uuid=uuid)
  File "/Library/Frameworks/Python.framework/Versions/3.10/lib/python3.10/site-packages/cryptofeed/connection.py", line 45, in process_response
    r.raise_for_status()
  File "/Library/Frameworks/Python.framework/Versions/3.10/lib/python3.10/site-packages/requests/models.py", line 1021, in raise_for_status
    raise HTTPError(http_error_msg, response=self)
requests.exceptions.HTTPError: 451 Client Error:  for url: https://fapi.binance.com/fapi/v1/exchangeInfo
